Workbook
Name Slicer_Completion_Status: #N/A
Name Slicer_Course_Name: #N/A
Name Slicer_Mode_of_Training: #N/A
Name Slicer_State: #N/A

Sheet Detail1
A1: Details for Total_Teachers - State: Kerala
A3: Certificate_Issued | B3: Training_Hours | C3: Region | D3: State | E3: Email_ID | F3: Experience_Years | G3: Certificate_Status_Clean | H3: Completed_Flag | I3: Enrollment_Flag | J3: Training_Duration_Days | K3: Experience_Band
A4: No | B4: 11 | C4: South | D4: Kerala | E4: teacher500@school.edu | F4: 10 | G4: No | H4: 0 | I4: 1 | J4: 59 | K4: 5-10 Years
A5: No | B5: 39 | C5: South | D5: Kerala | E5: teacher2@school.edu | F5: 3 | G5: No | H5: 0 | I5: 1 | J5: 36 | K5: 0-5 Years
A6: Yes | B6: 43 | C6: South | D6: Kerala | E6: teacher492@school.edu | F6: 13 | G6: Yes | H6: 1 | I6: 1 | J6: 55 | K6: 11-20 Years
A7: No | B7: 27 | C7: North | D7: Kerala | E7: teacher490@school.edu | F7: 4 | G7: No | H7: 0 | I7: 1 | J7: 45 | K7: 0-5 Years
A8: No | B8: 56 | C8: North | D8: Kerala | E8: teacher484@school.edu | F8: 8 | G8: No | H8: 0 | I8: 1 | J8: 50 | K8: 5-10 Years
A9: No | B9: 33 | C9: West | D9: Kerala | E9: teacher476@school.edu | F9: 21 | G9: No | H9: 0 | I9: 1 | J9: 52 | K9: 20+ Years
A10: No | B10: 36 | C10: West | D10: Kerala | E10: teacher475@school.edu | F10: 20 | G10: No | H10: 0 | I10: 1 | J10: 7 | K10: 11-20 Years
A11: No | B11: 59 | C11: East | D11: Kerala | E11: teacher473@school.edu | F11: 10 | G11: No | H11: 0 | I11: 1 | J11: 56 | K11: 5-10 Years
A12: No | B12: 49 | C12: East | D12: Kerala | E12: teacher464@school.edu | F12: 12 | G12: No | H12: 0 | I12: 1 | J12: 48 | K12: 11-20 Years
A13: Yes | B13: 9 | C13: South | D13: Kerala | E13: teacher456@school.edu | F13: 21 | G13: Yes | H13: 1 | I13: 1 | J13: 36 | K13: 20+ Years
A14: No | B14: 34 | C14: South | D14: Kerala | E14: teacher454@school.edu | F14: 5 | G14: No | H14: 0 | I14: 1 | J14: 16 | K14: 0-5 Years
A15: No | B15: 5 | C15: North | D15: Kerala | E15: teacher451@school.edu | F15: 29 | G15: No | H15: 0 | I15: 1 | J15: 39 | K15: 20+ Years
... A106: No | B106: 38 | C106: South | D106: Kerala | E106: teacher109@school.edu | F106: 14 | G106: No | H106: 0 | I106: 1 | J106: 31 | K106: 11-20 Years

Sheet Pivots
A2: 1.Course-wise Teacher Enrollment | G2: 5.Experience vs Completion
A3: Row Labels | B3: Total Teachers | G3: Row Labels | H3: Sum of Enrollment_Flag | I3: Sum of Completed_Flag | J3: Completed Percentage
A4: Inclusive Education | B4: 119 | C4: Inclusive Education | D4: 119 | G4: 0-5 Years | H4: 79 | I4: 24 | J4: 0.30379747 | K4: 0-5 Years | L4: 0.30379747
A5: EdTech Tools | B5: 102 | C5: EdTech Tools | D5: 102 | G5: 11-20 Years | H5: 137 | I5: 60 | J5: 0.4379562 | K5: 11-20 Years | L5: 0.4379562
A6: Digital Teaching | B6: 93 | C6: Digital Teaching | D6: 93 | G6: 20+ Years | H6: 205 | I6: 61 | J6: 0.29756098 | K6: 20+ Years | L6: 0.29756098
A7: Classroom Management | B7: 96 | C7: Classroom Management | D7: 96 | G7: 5-10 Years | H7: 79 | I7: 21 | J7: 0.26582278 | K7: 5-10 Years | L7: 0.26582278
A8: Assessment Skills | B8: 90 | C8: Assessment Skills | D8: 90 | G8: Grand Total | H8: 500 | I8: 166 | J8: 0.332
A9: Grand Total | B9: 500
A10: 2.Course-wise Completion Rate | G10: 6.Mode of Training Effectiveness
A11: Row Labels | B11: Total_Enrolled | C11: Completed | D11: Sum of Completion Rate | G11: Row Labels | H11: Sum of Completed_Flag | I11: Sum of Enrollment_Flag | J11: Average of Completion Rate
A12: Assessment Skills | B12: 90 | C12: 31 | D12: 0.34444444 | G12: Hybrid | H12: 52 | I12: 156 | J12: 0.33333333 | K12: Hybrid | L12: 0.33333333
A13: Classroom Management | B13: 96 | C13: 37 | D13: 0.38541667 | G13: Offline | H13: 60 | I13: 172 | J13: 0.34883721 | K13: Offline | L13: 0.34883721
A14: Digital Teaching | B14: 93 | C14: 27 | D14: 0.29032258 | G14: Online | H14: 54 | I14: 172 | J14: 0.31395349 | K14: Online | L14: 0.31395349
A15: EdTech Tools | B15: 102 | C15: 28 | D15: 0.2745098 | G15: Grand Total | H15: 166 | I15: 500 | J15: 0.332
A16: Inclusive Education | B16: 119 | C16: 43 | D16: 0.36134454
A17: Grand Total | B17: 500 | C17: 166 | D17: 0.332
A18: 3.State-wise Teacher Distribution | G18: 7.Training Hours Insight | J18: 8.Teacher Drill-Down Table (IMPORTANT)
A19: Row Labels | B19: Total_Teachers | G19: Row Labels | H19: Average of Training_Hours
A20: Delhi | B20: 96 | G20: Delhi | H20: 33.28125 | J20: Course_Name | K20: (All)
A21: Karnataka | B21: 102 | G21: Karnataka | H21: 30.676471 | J21: State | K21: (All)
A22: Kerala | B22: 103 | G22: Kerala | H22: 30.951456
A23: Maharashtra | B23: 106 | G23: Maharashtra | H23: 31.141509 | J23: Row Labels | K23: Count of Completion_Status
A24: Tamil Nadu | B24: 93 | G24: Tamil Nadu | H24: 29.698925 | J24: Amit K | K24: 12
A25: Grand Total | B25: 500 | G25: Grand Total | H25: 31.15 | J25: Amit M | K25: 11
A26: 4.State-wise Completion Performance | J26: Amit R | K26: 18
A27: Row Labels | B27: Sum of Completed_Flag | C27: Sum of Enrollment_Flag | D27: Sum of State Completion % | J27: Amit S | K27: 10
A28: Delhi | B28: 40 | C28: 96 | D28: 0.41666667 | J28: Anjali K | K28: 8
A29: Karnataka | B29: 38 | C29: 102 | D29: 0.37254902 | J29: Anjali M | K29: 15
A30: Kerala | B30: 27 | C30: 103 | D30: 0.26213592 | J30: Anjali R | K30: 12
A31: Maharashtra | B31: 36 | C31: 106 | D31: 0.33962264 | J31: Anjali S | K31: 13
A32: Tamil Nadu | B32: 25 | C32: 93 | D32: 0.2688172 | J32: Kiran K | K32: 19
A33: Grand Total | B33: 166 | C33: 500 | D33: 0.332 | J33: Kiran M | K33: 12
J34: Kiran R | K34: 17
A35: Delhi | B35: 0.41666667 | J35: Kiran S | K35: 22
A36: Karnataka | B36: 0.37254902 | J36: Neha K | K36: 8
A37: Kerala | B37: 0.26213592 | J37: Neha M | K37: 9
A38: Maharashtra | B38: 0.33962264 | J38: Neha R | K38: 18
A39: Tamil Nadu | B39: 0.2688172 | J39: Neha S | K39: 5
J40: Pooja K | K40: 11
J41: Pooja M | K41: 15
...

Sheet Dashboard
G1: Teacher Upskilling Dashboard
G2: Interactive analysis of course enrollment, completion, and regional performance
E16: Course-wise Enrollment | N16: State-wise Distribution
AE35: Top courses | AF35: =MAX(Pivots!D4:D8) -> 119
AE36: Max Enrolment | AF36: =INDEX(Pivots!C4:C8, MATCH(AF35, Pivots!D4:D8, 0)) -> Inclusive Education
AE37: Max Completion % | AF37: =MAX(Pivots!B35:B39) -> 0.41666667
AE38: Best state | AF38: =INDEX(Pivots!A35:A39, MATCH(Dashboard!AF37, Pivots!B35:B39, 0)) -> Delhi
B39: Completion Rate by Course | O39: Mode of Training Effectiveness | AE39: Best Mode | AF39: =MAX(Pivots!L11:L13) -> 0.34883721
AE40: Completation rate | AF40: =INDEX(Pivots!K12:K14, MATCH(AF39, Pivots!L12:L14, 0)) -> Offline
AE41: Experience Band Insight | AF41: =MAX(Pivots!L4:L8) -> 0.4379562
AF42: =INDEX(Pivots!K4:K10, MATCH(AF41, Pivots!L4:L8, 0)) -> 11-20 Years
AF44: ="• "&AF36&" is the most enrolled course with "&AF35&" teachers." -> • Inclusive Education is the most enrolled course with 119 teachers.
AF45: ="• "&AF38&" shows the highest completion rate ("&TEXT(AF37,"0%")&")." -> • Delhi shows the highest completion rate (42%).
AF46: ="• "&AF40&" Mode shows the highest completion rate ("&TEXT(AF39,"0%")&")." -> • Offline Mode shows the highest completion rate (35%).
AF47: ="• "&AF42&" experienced reachers has the highest completion rate ("&TEXT(AF41,"0%")&")." -> • 11-20 Years experienced reachers has the highest completion rate (44%).
AF50: =AF44 & CHAR(10) & AF45 & CHAR(10) & AF46 & CHAR(10) & AF47 & CHAR(10) -> • Inclusive Education is the most enrolled course with 119 teachers. • Delhi shows the highest completion rate (42%). • Offline Mode shows the highest completion rate (35%). • 11-20 Years experienced reachers has the highest completion rate (44%).
B56: Experience vs Completion | O56: Key Insights
Q70: How to use:
P71: • Use slicers to filter by course, state, or mode
P72: • Charts and insights update automatically
P73: • Click chart bars to drill down (where applicable)

Sheet Teacher_Course_Completion
A1: Teacher_ID | B1: Teacher_Name | C1: Gender | D1: Age | E1: School_Name | F1: Subject | G1: Course_Name | H1: Course_Category | I1: Mode_of_Training | J1: Start_Date | K1: End_Date | L1: Completion_Status | M1: Completion_Percentage | N1: Assessment_Score | O1: Certificate_Issued | P1: Training_Hours | Q1: Region | R1: State | S1: Email_ID | T1: Experience_Years | U1: Certificate_Status_Clean | V1: Completed_Flag | W1: Enrollment_Flag | X1: Training_Duration_Days | Y1: Experience_Band
A2: T0001 | B2: Suresh R | C2: Female | D2: 47 | E2: Public School | F2: Science | G2: EdTech Tools | H2: Assessment | I2: Offline | J2: 45406 | K2: 45419 | L2: In Progress | M2: 67 | O2: No | P2: 32 | Q2: North | R2: Delhi | S2: teacher1@school.edu | T2: 3 | U2: =IF(Teacher_Data[[#This Row],[Completion_Status]]="Completed","Yes","No") -> No | V2: =IF(Teacher_Data[[#This Row],[Completion_Status]]="Completed",1,0) -> 0 | W2: =1 -> 1 | X2: =Teacher_Data[[#This Row],[End_Date]]-Teacher_Data[[#This Row],[Start_Date]] -> 13 | Y2: =_xlfn.IFS(Teacher_Data[[#This Row],[Experience_Years]]<=5,"0-5 Years",Teacher_Data[[#This Row],[Experience_Years]]<=10,"5-10 Years",Teacher_Data[[#This Row],[Experience_Years]]<=20,"11-20 Years",TRUE,"20+ Years") -> 0-5 Years
A3: T0002 | B3: Amit K | C3: Male | D3: 22 | E3: International School | F3: Social Science | G3: Digital Teaching | H3: Professional Development | I3: Offline | J3: 45441 | K3: 45477 | L3: In Progress | M3: 45 | O3: No | P3: 39 | Q3: South | R3: Kerala | S3: teacher2@school.edu | T3: 3 | U3: =IF(Teacher_Data[[#This Row],[Completion_Status]]="Completed","Yes","No") -> No | V3: =IF(Teacher_Data[[#This Row],[Completion_Status]]="Completed",1,0) -> 0 | W3: =1 -> 1 | X3: =Teacher_Data[[#This Row],[End_Date]]-Teacher_Data[[#This Row],[Start_Date]] -> 36 | Y3: =_xlfn.IFS(Teacher_Data[[#This Row],[Experience_Years]]<=5,"0-5 Years",Teacher_Data[[#This Row],[Experience_Years]]<=10,"5-10 Years",Teacher_Data[[#This Row],[Experience_Years]]<=20,"11-20 Years",TRUE,"20+ Years") -> 0-5 Years
A4: T0003 | B4: Priya S | C4: Female | D4: 33 | E4: Public School | F4: Science | G4: Classroom Management | H4: Assessment | I4: Online | J4: 45360 | K4: 45380 | L4: In Progress | M4: 53 | O4: No | P4: 39 | Q4: South | R4: Delhi | S4: teacher3@school.edu | T4: 3 | U4: =IF(Teacher_Data[[#This Row],[Completion_Status]]="Completed","Yes","No") -> No | V4: =IF(Teacher_Data[[#This Row],[Completion_Status]]="Completed",1,0) -> 0 | W4: =1 -> 1 | X4: =Teacher_Data[[#This Row],[End_Date]]-Teacher_Data[[#This Row],[Start_Date]] -> 20 | Y4: =_xlfn.IFS(Teacher_Data[[#This Row],[Experience_Years]]<=5,"0-5 Years",Teacher_Data[[#This Row],[Experience_Years]]<=10,"5-10 Years",Teacher_Data[[#This Row],[Experience_Years]]<=20,"11-20 Years",TRUE,"20+ Years") -> 0-5 Years
A5: T0004 | B5: Ravi R | C5: Female | D5: 43 | E5: Public School | F5: Social Science | G5: Classroom Management | H5: Pedagogy | I5: Hybrid | J5: 45429 | K5: 45488 | L5: Completed | M5: 78 | N5: 92 | O5: Yes | P5: 13 | Q5: North | R5: Delhi | S5: teacher4@school.edu | T5: 13 | U5: =IF(Teacher_Data[[#This Row],[Completion_Status]]="Completed","Yes","No") -> Yes | V5: =IF(Teacher_Data[[#This Row],[Completion_Status]]="Completed",1,0) -> 1 | W5: =1 -> 1 | X5: =Teacher_Data[[#This Row],[End_Date]]-Teacher_Data[[#This Row],[Start_Date]] -> 59 | Y5: =_xlfn.IFS(Teacher_Data[[#This Row],[Experience_Years]]<=5,"0-5 Years",Teacher_Data[[#This Row],[Experience_Years]]<=10,"5-10 Years",Teacher_Data[[#This Row],[Experience_Years]]<=20,"11-20 Years",TRUE,"20+ Years") -> 11-20 Years
A6: T0005 | B6: Rahul M | C6: Female | D6: 37 | E6: Central School | F6: Social Science | G6: Inclusive Education | H6: Technology | I6: Online | J6: 45440 | K6: 45496 | L6: Not Completed | M6: 1 | O6: No | P6: 52 | Q6: West | R6: Maharashtra | S6: teacher5@school.edu | T6: 19 | U6: =IF(Teacher_Data[[#This Row],[Completion_Status]]="Completed","Yes","No") -> No | V6: =IF(Teacher_Data[[#This Row],[Completion_Status]]="Completed",1,0) -> 0 | W6: =1 -> 1 | X6: =Teacher_Data[[#This Row],[End_Date]]-Teacher_Data[[#This Row],[Start_Date]] -> 56 | Y6: =_xlfn.IFS(Teacher_Data[[#This Row],[Experience_Years]]<=5,"0-5 Years",Teacher_Data[[#This Row],[Experience_Years]]<=10,"5-10 Years",Teacher_Data[[#This Row],[Experience_Years]]<=20,"11-20 Years",TRUE,"20+ Years") -> 11-20 Years
A7: T0006 | B7: Sneha M | C7: Male | D7: 33 | E7: Govt High School | F7: Maths | G7: EdTech Tools | H7: Technology | I7: Hybrid | J7: 45545 | K7: 45564 | L7: Completed | M7: 73 | N7: 56 | O7: Yes | P7: 24 | Q7: East | R7: Delhi | S7: teacher6@school.edu | T7: 8 | U7: =IF(Teacher_Data[[#This Row],[Completion_Status]]="Completed","Yes","No") -> Yes | V7: =IF(Teacher_Data[[#This Row],[Completion_Status]]="Completed",1,0) -> 1 | W7: =1 -> 1 | X7: =Teacher_Data[[#This Row],[End_Date]]-Teacher_Data[[#This Row],[Start_Date]] -> 19 | Y7: =_xlfn.IFS(Teacher_Data[[#This Row],[Experience_Years]]<=5,"0-5 Years",Teacher_Data[[#This Row],[Experience_Years]]<=10,"5-10 Years",Teacher_Data[[#This Row],[Experience_Years]]<=20,"11-20 Years",TRUE,"20+ Years") -> 5-10 Years
A8: T0007 | B8: Rahul R | C8: Female | D8: 49 | E8: International School | F8: Maths | G8: Classroom Management | H8: Technology | I8: Offline | J8: 45458 | K8: 45480 | L8: Completed | M8: 84 | N8: 67 | O8: Yes | P8: 27 | Q8: East | R8: Karnataka | S8: teacher7@school.edu | T8: 15 | U8: =IF(Teacher_Data[[#This Row],[Completion_Status]]="Completed","Yes","No") -> Yes | V8: =IF(Teacher_Data[[#This Row],[Completion_Status]]="Completed",1,0) -> 1 | W8: =1 -> 1 | X8: =Teacher_Data[[#This Row],[End_Date]]-Teacher_Data[[#This Row],[Start_Date]] -> 22 | Y8: =_xlfn.IFS(Teacher_Data[[#This Row],[Experience_Years]]<=5,"0-5 Years",Teacher_Data[[#This Row],[Experience_Years]]<=10,"5-10 Years",Teacher_Data[[#This Row],[Experience_Years]]<=20,"11-20 Years",TRUE,"20+ Years") -> 11-20 Years
A9: T0008 | B9: Neha K | C9: Female | D9: 41 | E9: Govt High School | F9: Social Science | G9: Assessment Skills | H9: Technology | I9: Online | J9: 45550 | K9: 45565 | L9: In Progress | M9: 81 | O9: No | P9: 54 | Q9: North | R9: Maharashtra | S9: teacher8@school.edu | T9: 35 | U9: =IF(Teacher_Data[[#This Row],[Completion_Status]]="Completed","Yes","No") -> No | V9: =IF(Teacher_Data[[#This Row],[Completion_Status]]="Completed",1,0) -> 0 | W9: =1 -> 1 | X9: =Teacher_Data[[#This Row],[End_Date]]-Teacher_Data[[#This Row],[Start_Date]] -> 15 | Y9: =_xlfn.IFS(Teacher_Data[[#This Row],[Experience_Years]]<=5,"0-5 Years",Teacher_Data[[#This Row],[Experience_Years]]<=10,"5-10 Years",Teacher_Data[[#This Row],[Experience_Years]]<=20,"11-20 Years",TRUE,"20+ Years") -> 20+ Years
A10: T0009 | B10: Suresh S | C10: Male | D10: 31 | E10: Govt High School | F10: Maths | G10: EdTech Tools | H10: Professional Development | I10: Online | J10: 45534 | K10: 45550 | L10: In Progress | M10: 67 | O10: No | P10: 45 | Q10: South | R10: Delhi | S10: teacher9@school.edu | T10: 25 | U10: =IF(Teacher_Data[[#This Row],[Completion_Status]]="Completed","Yes","No") -> No | V10: =IF(Teacher_Data[[#This Row],[Completion_Status]]="Completed",1,0) -> 0 | W10: =1 -> 1 | X10: =Teacher_Data[[#This Row],[End_Date]]-Teacher_Data[[#This Row],[Start_Date]] -> 16 | Y10: =_xlfn.IFS(Teacher_Data[[#This Row],[Experience_Years]]<=5,"0-5 Years",Teacher_Data[[#This Row],[Experience_Years]]<=10,"5-10 Years",Teacher_Data[[#This Row],[Experience_Years]]<=20,"11-20 Years",TRUE,"20+ Years") -> 20+ Years
A11: T0010 | B11: Sneha K | C11: Female | D11: 29 | E11: Central School | F11: English | G11: EdTech Tools | H11: Professional Development | I11: Online | J11: 45357 | K11: 45415 | L11: Completed | M11: 92 | N11: 92 | O11: Yes | P11: 45 | Q11: South | R11: Maharashtra | S11: teacher10@school.edu | T11: 23 | U11: =IF(Teacher_Data[[#This Row],[Completion_Status]]="Completed","Yes","No") -> Yes | V11: =IF(Teacher_Data[[#This Row],[Completion_Status]]="Completed",1,0) -> 1 | W11: =1 -> 1 | X11: =Teacher_Data[[#This Row],[End_Date]]-Teacher_Data[[#This Row],[Start_Date]] -> 58 | Y11: =_xlfn.IFS(Teacher_Data[[#This Row],[Experience_Years]]<=5,"0-5 Years",Teacher_Data[[#This Row],[Experience_Years]]<=10,"5-10 Years",Teacher_Data[[#This Row],[Experience_Years]]<=20,"11-20 Years",TRUE,"20+ Years") -> 20+ Years
A12: T0011 | B12: Ravi M | C12: Male | D12: 59 | E12: Govt High School | F12: English | G12: Inclusive Education | H12: Assessment | I12: Offline | J12: 45299 | K12: 45343 | L12: Not Completed | M12: 4 | O12: No | P12: 24 | Q12: South | R12: Maharashtra | S12: teacher11@school.edu | T12: 15 | U12: =IF(Teacher_Data[[#This Row],[Completion_Status]]="Completed","Yes","No") -> No | V12: =IF(Teacher_Data[[#This Row],[Completion_Status]]="Completed",1,0) -> 0 | W12: =1 -> 1 | X12: =Teacher_Data[[#This Row],[End_Date]]-Teacher_Data[[#This Row],[Start_Date]] -> 44 | Y12: =_xlfn.IFS(Teacher_Data[[#This Row],[Experience_Years]]<=5,"0-5 Years",Teacher_Data[[#This Row],[Experience_Years]]<=10,"5-10 Years",Teacher_Data[[#This Row],[Experience_Years]]<=20,"11-20 Years",TRUE,"20+ Years") -> 11-20 Years
A13: T0012 | B13: Kiran R | C13: Male | D13: 41 | E13: International School | F13: Science | G13: Digital Teaching | H13: Pedagogy | I13: Online | J13: 45518 | K13: 45529 | L13: In Progress | M13: 97 | O13: No | P13: 7 | Q13: East | R13: Karnataka | S13: teacher12@school.edu | T13: 31 | U13: =IF(Teacher_Data[[#This Row],[Completion_Status]]="Completed","Yes","No") -> No | V13: =IF(Teacher_Data[[#This Row],[Completion_Status]]="Completed",1,0) -> 0 | W13: =1 -> 1 | X13: =Teacher_Data[[#This Row],[End_Date]]-Teacher_Data[[#This Row],[Start_Date]] -> 11 | Y13: =_xlfn.IFS(Teacher_Data[[#This Row],[Experience_Years]]<=5,"0-5 Years",Teacher_Data[[#This Row],[Experience_Years]]<=10,"5-10 Years",Teacher_Data[[#This Row],[Experience_Years]]<=20,"11-20 Years",TRUE,"20+ Years") -> 20+ Years
A14: T0013 | B14: Rahul R | C14: Female | D14: 23 | E14: Govt High School | F14: Social Science | G14: Inclusive Education | H14: Pedagogy | I14: Online | J14: 45504 | K14: 45554 | L14: Not Completed | M14: 1 | O14: No | P14: 44 | Q14: West | R14: Kerala | S14: teacher13@school.edu | T14: 34 | U14: =IF(Teacher_Data[[#This Row],[Completion_Status]]="Completed","Yes","No") -> No | V14: =IF(Teacher_Data[[#This Row],[Completion_Status]]="Completed",1,0) -> 0 | W14: =1 -> 1 | X14: =Teacher_Data[[#This Row],[End_Date]]-Teacher_Data[[#This Row],[Start_Date]] -> 50 | Y14: =_xlfn.IFS(Teacher_Data[[#This Row],[Experience_Years]]<=5,"0-5 Years",Teacher_Data[[#This Row],[Experience_Years]]<=10,"5-10 Years",Teacher_Data[[#This Row],[Experience_Years]]<=20,"11-20 Years",TRUE,"20+ Years") -> 20+ Years
A15: T0014 | B15: Kiran M | C15: Male | D15: 42 | E15: Central School | F15: Science | G15: Digital Teaching | H15: Pedagogy | I15: Hybrid | J15: 45353 | K15: 45401 | L15: In Progress | M15: 99 | O15: No | P15: 23 | Q15: South | R15: Delhi | S15: teacher14@school.edu | T15: 34 | U15: =IF(Teacher_Data[[#This Row],[Completion_Status]]="Completed","Yes","No") -> No | V15: =IF(Teacher_Data[[#This Row],[Completion_Status]]="Completed",1,0) -> 0 | W15: =1 -> 1 | X15: =Teacher_Data[[#This Row],[End_Date]]-Teacher_Data[[#This Row],[Start_Date]] -> 48 | Y15: =_xlfn.IFS(Teacher_Data[[#This Row],[Experience_Years]]<=5,"0-5 Years",Teacher_Data[[#This Row],[Experience_Years]]<=10,"5-10 Years",Teacher_Data[[#This Row],[Experience_Years]]<=20,"11-20 Years",TRUE,"20+ Years") -> 20+ Years
A16: T0015 | B16: Ravi M | C16: Female | D16: 53 | E16: Central School | F16: English | G16: Classroom Management | H16: Professional Development | I16: Offline | J16: 45578 | K16: 45590 | L16: Completed | M16: 73 | N16: 56 | O16: Yes | P16: 36 | Q16: South | R16: Delhi | S16: teacher15@school.edu | T16: 18 | U16: =IF(Teacher_Data[[#This Row],[Completion_Status]]="Completed","Yes","No") -> Yes | V16: =IF(Teacher_Data[[#This Row],[Completion_Status]]="Completed",1,0) -> 1 | W16: =1 -> 1 | X16: =Teacher_Data[[#This Row],[End_Date]]-Teacher_Data[[#This Row],[Start_Date]] -> 12 | Y16: =_xlfn.IFS(Teacher_Data[[#This Row],[Experience_Years]]<=5,"0-5 Years",Teacher_Data[[#This Row],[Experience_Years]]<=10,"5-10 Years",Teacher_Data[[#This Row],[Experience_Years]]<=20,"11-20 Years",TRUE,"20+ Years") -> 11-20 Years
A17: T0016 | B17: Priya R | C17: Female | D17: 47 | E17: Govt High School | F17: Computer Science | G17: Assessment Skills | H17: Assessment | I17: Online | J17: 45378 | K17: 45414 | L17: Not Completed | M17: 13 | O17: No | P17: 48 | Q17: North | R17: Karnataka | S17: teacher16@school.edu | T17: 31 | U17: =IF(Teacher_Data[[#This Row],[Completion_Status]]="Completed","Yes","No") -> No | V17: =IF(Teacher_Data[[#This Row],[Completion_Status]]="Completed",1,0) -> 0 | W17: =1 -> 1 | X17: =Teacher_Data[[#This Row],[End_Date]]-Teacher_Data[[#This Row],[Start_Date]] -> 36 | Y17: =_xlfn.IFS(Teacher_Data[[#This Row],[Experience_Years]]<=5,"0-5 Years",Teacher_Data[[#This Row],[Experience_Years]]<=10,"5-10 Years",Teacher_Data[[#This Row],[Experience_Years]]<=20,"11-20 Years",TRUE,"20+ Years") -> 20+ Years
A18: T0017 | B18: Pooja R | C18: Male | D18: 59 | E18: Central School | F18: Computer Science | G18: Inclusive Education | H18: Assessment | I18: Online | J18: 45364 | K18: 45397 | L18: In Progress | M18: 50 | O18: No | P18: 52 | Q18: West | R18: Tamil Nadu | S18: teacher17@school.edu | T18: 33 | U18: =IF(Teacher_Data[[#This Row],[Completion_Status]]="Completed","Yes","No") -> No | V18: =IF(Teacher_Data[[#This Row],[Completion_Status]]="Completed",1,0) -> 0 | W18: =1 -> 1 | X18: =Teacher_Data[[#This Row],[End_Date]]-Teacher_Data[[#This Row],[Start_Date]] -> 33 | Y18: =_xlfn.IFS(Teacher_Data[[#This Row],[Experience_Years]]<=5,"0-5 Years",Teacher_Data[[#This Row],[Experience_Years]]<=10,"5-10 Years",Teacher_Data[[#This Row],[Experience_Years]]<=20,"11-20 Years",TRUE,"20+ Years") -> 20+ Years
A19: T0018 | B19: Anjali S | C19: Male | D19: 29 | E19: International School | F19: Computer Science | G19: Classroom Management | H19: Assessment | I19: Hybrid | J19: 45390 | K19: 45422 | L19: Not Completed | M19: 21 | O19: No | P19: 17 | Q19: South | R19: Tamil Nadu | S19: teacher18@school.edu | T19: 32 | U19: =IF(Teacher_Data[[#This Row],[Completion_Status]]="Completed","Yes","No") -> No | V19: =IF(Teacher_Data[[#This Row],[Completion_Status]]="Completed",1,0) -> 0 | W19: =1 -> 1 | X19: =Teacher_Data[[#This Row],[End_Date]]-Teacher_Data[[#This Row],[Start_Date]] -> 32 | Y19: =_xlfn.IFS(Teacher_Data[[#This Row],[Experience_Years]]<=5,"0-5 Years",Teacher_Data[[#This Row],[Experience_Years]]<=10,"5-10 Years",Teacher_Data[[#This Row],[Experience_Years]]<=20,"11-20 Years",TRUE,"20+ Years") -> 20+ Years
A20: T0019 | B20: Kiran S | C20: Male | D20: 47 | E20: Govt High School | F20: Science | G20: Inclusive Education | H20: Technology | I20: Offline | J20: 45484 | K20: 45520 | L20: Completed | M20: 41 | N20: 88 | O20: Yes | P20: 16 | Q20: East | R20: Kerala | S20: teacher19@school.edu | T20: 20 | U20: =IF(Teacher_Data[[#This Row],[Completion_Status]]="Completed","Yes","No") -> Yes | V20: =IF(Teacher_Data[[#This Row],[Completion_Status]]="Completed",1,0) -> 1 | W20: =1 -> 1 | X20: =Teacher_Data[[#This Row],[End_Date]]-Teacher_Data[[#This Row],[Start_Date]] -> 36 | Y20: =_xlfn.IFS(Teacher_Data[[#This Row],[Experience_Years]]<=5,"0-5 Years",Teacher_Data[[#This Row],[Experience_Years]]<=10,"5-10 Years",Teacher_Data[[#This Row],[Experience_Years]]<=20,"11-20 Years",TRUE,"20+ Years") -> 11-20 Years
A21: T0020 | B21: Priya R | C21: Female | D21: 30 | E21: International School | F21: Computer Science | G21: Digital Teaching | H21: Assessment | I21: Online | J21: 45518 | K21: 45523 | L21: Not Completed | M21: 5 | O21: No | P21: 22 | Q21: North | R21: Karnataka | S21: teacher20@school.edu | T21: 5 | U21: =IF(Teacher_Data[[#This Row],[Completion_Status]]="Completed","Yes","No") -> No | V21: =IF(Teacher_Data[[#This Row],[Completion_Status]]="Completed",1,0) -> 0 | W21: =1 -> 1 | X21: =Teacher_Data[[#This Row],[End_Date]]-Teacher_Data[[#This Row],[Start_Date]] -> 5 | Y21: =_xlfn.IFS(Teacher_Data[[#This Row],[Experience_Years]]<=5,"0-5 Years",Teacher_Data[[#This Row],[Experience_Years]]<=10,"5-10 Years",Teacher_Data[[#This Row],[Experience_Years]]<=20,"11-20 Years",TRUE,"20+ Years") -> 0-5 Years
A22: T0021 | B22: Amit R | C22: Male | D22: 32 | E22: Central School | F22: English | G22: Assessment Skills | H22: Pedagogy | I22: Offline | J22: 45534 | K22: 45570 | L22: In Progress | M22: 98 | O22: No | P22: 33 | Q22: South | R22: Tamil Nadu | S22: teacher21@school.edu | T22: 33 | U22: =IF(Teacher_Data[[#This Row],[Completion_Status]]="Completed","Yes","No") -> No | V22: =IF(Teacher_Data[[#This Row],[Completion_Status]]="Completed",1,0) -> 0 | W22: =1 -> 1 | X22: =Teacher_Data[[#This Row],[End_Date]]-Teacher_Data[[#This Row],[Start_Date]] -> 36 | Y22: =_xlfn.IFS(Teacher_Data[[#This Row],[Experience_Years]]<=5,"0-5 Years",Teacher_Data[[#This Row],[Experience_Years]]<=10,"5-10 Years",Teacher_Data[[#This Row],[Experience_Years]]<=20,"11-20 Years",TRUE,"20+ Years") -> 20+ Years
A23: T0022 | B23: Neha R | C23: Male | D23: 52 | E23: Central School | F23: Maths | G23: EdTech Tools | H23: Technology | I23: Offline | J23: 45575 | K23: 45597 | L23: In Progress | M23: 93 | O23: No | P23: 38 | Q23: North | R23: Delhi | S23: teacher22@school.edu | T23: 8 | U23: =IF(Teacher_Data[[#This Row],[Completion_Status]]="Completed","Yes","No") -> No | V23: =IF(Teacher_Data[[#This Row],[Completion_Status]]="Completed",1,0) -> 0 | W23: =1 -> 1 | X23: =Teacher_Data[[#This Row],[End_Date]]-Teacher_Data[[#This Row],[Start_Date]] -> 22 | Y23: =_xlfn.IFS(Teacher_Data[[#This Row],[Experience_Years]]<=5,"0-5 Years",Teacher_Data[[#This Row],[Experience_Years]]<=10,"5-10 Years",Teacher_Data[[#This Row],[Experience_Years]]<=20,"11-20 Years",TRUE,"20+ Years") -> 5-10 Years
A24: T0023 | B24: Suresh M | C24: Female | D24: 58 | E24: Public School | F24: Computer Science | G24: Digital Teaching | H24: Technology | I24: Hybrid | J24: 45302 | K24: 45336 | L24: Completed | M24: 77 | N24: 65 | O24: Yes | P24: 48 | Q24: East | R24: Karnataka | S24: teacher23@school.edu | T24: 24 | U24: =IF(Teacher_Data[[#This Row],[Completion_Status]]="Completed","Yes","No") -> Yes | V24: =IF(Teacher_Data[[#This Row],[Completion_Status]]="Completed",1,0) -> 1 | W24: =1 -> 1 | X24: =Teacher_Data[[#This Row],[End_Date]]-Teacher_Data[[#This Row],[Start_Date]] -> 34 | Y24: =_xlfn.IFS(Teacher_Data[[#This Row],[Experience_Years]]<=5,"0-5 Years",Teacher_Data[[#This Row],[Experience_Years]]<=10,"5-10 Years",Teacher_Data[[#This Row],[Experience_Years]]<=20,"11-20 Years",TRUE,"20+ Years") -> 20+ Years
A25: T0024 | B25: Anjali M | C25: Male | D25: 23 | E25: Public School | F25: Social Science | G25: Inclusive Education | H25: Technology | I25: Offline | J25: 45523 | K25: 45535 | L25: In Progress | M25: 92 | O25: No | P25: 22 | Q25: North | R25: Tamil Nadu | S25: teacher24@school.edu | T25: 14 | U25: =IF(Teacher_Data[[#This Row],[Completion_Status]]="Completed","Yes","No") -> No | V25: =IF(Teacher_Data[[#This Row],[Completion_Status]]="Completed",1,0) -> 0 | W25: =1 -> 1 | X25: =Teacher_Data[[#This Row],[End_Date]]-Teacher_Data[[#This Row],[Start_Date]] -> 12 | Y25: =_xlfn.IFS(Teacher_Data[[#This Row],[Experience_Years]]<=5,"0-5 Years",Teacher_Data[[#This Row],[Experience_Years]]<=10,"5-10 Years",Teacher_Data[[#This Row],[Experience_Years]]<=20,"11-20 Years",TRUE,"20+ Years") -> 11-20 Years
A26: T0025 | B26: Suresh S | C26: Male | D26: 32 | E26: Public School | F26: Computer Science | G26: Assessment Skills | H26: Professional Development | I26: Offline | J26: 45548 | K26: 45584 | L26: In Progress | M26: 69 | O26: No | P26: 15 | Q26: West | R26: Tamil Nadu | S26: teacher25@school.edu | T26: 1 | U26: =IF(Teacher_Data[[#This Row],[Completion_Status]]="Completed","Yes","No") -> No | V26: =IF(Teacher_Data[[#This Row],[Completion_Status]]="Completed",1,0) -> 0 | W26: =1 -> 1 | X26: =Teacher_Data[[#This Row],[End_Date]]-Teacher_Data[[#This Row],[Start_Date]] -> 36 | Y26: =_xlfn.IFS(Teacher_Data[[#This Row],[Experience_Years]]<=5,"0-5 Years",Teacher_Data[[#This Row],[Experience_Years]]<=10,"5-10 Years",Teacher_Data[[#This Row],[Experience_Years]]<=20,"11-20 Years",TRUE,"20+ Years") -> 0-5 Years
A27: T0026 | B27: Neha R | C27: Male | D27: 25 | E27: Public School | F27: Social Science | G27: Inclusive Education | H27: Assessment | I27: Hybrid | J27: 45573 | K27: 45632 | L27: Completed | M27: 74 | N27: 75 | O27: Yes | P27: 30 | Q27: South | R27: Tamil Nadu | S27: teacher26@school.edu | T27: 18 | U27: =IF(Teacher_Data[[#This Row],[Completion_Status]]="Completed","Yes","No") -> Yes | V27: =IF(Teacher_Data[[#This Row],[Completion_Status]]="Completed",1,0) -> 1 | W27: =1 -> 1 | X27: =Teacher_Data[[#This Row],[End_Date]]-Teacher_Data[[#This Row],[Start_Date]] -> 59 | Y27: =_xlfn.IFS(Teacher_Data[[#This Row],[Experience_Years]]<=5,"0-5 Years",Teacher_Data[[#This Row],[Experience_Years]]<=10,"5-10 Years",Teacher_Data[[#This Row],[Experience_Years]]<=20,"11-20 Years",TRUE,"20+ Years") -> 11-20 Years
A28: T0027 | B28: Priya S | C28: Male | D28: 29 | E28: Govt High School | F28: English | G28: Classroom Management | H28: Technology | I28: Hybrid | J28: 45474 | K28: 45500 | L28: In Progress | M28: 63 | O28: No | P28: 31 | Q28: North | R28: Delhi | S28: teacher27@school.edu | T28: 16 | U28: =IF(Teacher_Data[[#This Row],[Completion_Status]]="Completed","Yes","No") -> No | V28: =IF(Teacher_Data[[#This Row],[Completion_Status]]="Completed",1,0) -> 0 | W28: =1 -> 1 | X28: =Teacher_Data[[#This Row],[End_Date]]-Teacher_Data[[#This Row],[Start_Date]] -> 26 | Y28: =_xlfn.IFS(Teacher_Data[[#This Row],[Experience_Years]]<=5,"0-5 Years",Teacher_Data[[#This Row],[Experience_Years]]<=10,"5-10 Years",Teacher_Data[[#This Row],[Experience_Years]]<=20,"11-20 Years",TRUE,"20+ Years") -> 11-20 Years
A29: T0028 | B29: Anjali K | C29: Male | D29: 53 | E29: Central School | F29: English | G29: EdTech Tools | H29: Pedagogy | I29: Online | J29: 45366 | K29: 45395 | L29: Completed | M29: 83 | N29: 99 | O29: Yes | P29: 19 | Q29: South | R29: Karnataka | S29: teacher28@school.edu | T29: 18 | U29: =IF(Teacher_Data[[#This Row],[Completion_Status]]="Completed","Yes","No") -> Yes | V29: =IF(Teacher_Data[[#This Row],[Completion_Status]]="Completed",1,0) -> 1 | W29: =1 -> 1 | X29: =Teacher_Data[[#This Row],[End_Date]]-Teacher_Data[[#This Row],[Start_Date]] -> 29 | Y29: =_xlfn.IFS(Teacher_Data[[#This Row],[Experience_Years]]<=5,"0-5 Years",Teacher_Data[[#This Row],[Experience_Years]]<=10,"5-10 Years",Teacher_Data[[#This Row],[Experience_Years]]<=20,"11-20 Years",TRUE,"20+ Years") -> 11-20 Years
A30: T0029 | B30: Anjali S | C30: Female | D30: 42 | E30: Public School | F30: Computer Science | G30: EdTech Tools | H30: Pedagogy | I30: Hybrid | J30: 45410 | K30: 45445 | L30: Not Completed | M30: 9 | O30: No | P30: 14 | Q30: East | R30: Kerala | S30: teacher29@school.edu | T30: 24 | U30: =IF(Teacher_Data[[#This Row],[Completion_Status]]="Completed","Yes","No") -> No | V30: =IF(Teacher_Data[[#This Row],[Completion_Status]]="Completed",1,0) -> 0 | W30: =1 -> 1 | X30: =Teacher_Data[[#This Row],[End_Date]]-Teacher_Data[[#This Row],[Start_Date]] -> 35 | Y30: =_xlfn.IFS(Teacher_Data[[#This Row],[Experience_Years]]<=5,"0-5 Years",Teacher_Data[[#This Row],[Experience_Years]]<=10,"5-10 Years",Teacher_Data[[#This Row],[Experience_Years]]<=20,"11-20 Years",TRUE,"20+ Years") -> 20+ Years
A31: T0030 | B31: Pooja R | C31: Male | D31: 23 | E31: Central School | F31: English | G31: Digital Teaching | H31: Professional Development | I31: Offline | J31: 45389 | K31: 45408 | L31: Completed | M31: 84 | N31: 93 | O31: Yes | P31: 11 | Q31: East | R31: Kerala | S31: teacher30@school.edu | T31: 21 | U31: =IF(Teacher_Data[[#This Row],[Completion_Status]]="Completed","Yes","No") -> Yes | V31: =IF(Teacher_Data[[#This Row],[Completion_Status]]="Completed",1,0) -> 1 | W31: =1 -> 1 | X31: =Teacher_Data[[#This Row],[End_Date]]-Teacher_Data[[#This Row],[Start_Date]] -> 19 | Y31: =_xlfn.IFS(Teacher_Data[[#This Row],[Experience_Years]]<=5,"0-5 Years",Teacher_Data[[#This Row],[Experience_Years]]<=10,"5-10 Years",Teacher_Data[[#This Row],[Experience_Years]]<=20,"11-20 Years",TRUE,"20+ Years") -> 20+ Years
A32: T0031 | B32: Pooja M | C32: Female | D32: 23 | E32: Central School | F32: Social Science | G32: Classroom Management | H32: Pedagogy | I32: Offline | J32: 45412 | K32: 45465 | L32: Not Completed | M32: 26 | O32: No | P32: 33 | Q32: North | R32: Maharashtra | S32: teacher31@school.edu | T32: 28 | U32: =IF(Teacher_Data[[#This Row],[Completion_Status]]="Completed","Yes","No") -> No | V32: =IF(Teacher_Data[[#This Row],[Completion_Status]]="Completed",1,0) -> 0 | W32: =1 -> 1 | X32: =Teacher_Data[[#This Row],[End_Date]]-Teacher_Data[[#This Row],[Start_Date]] -> 53 | Y32: =_xlfn.IFS(Teacher_Data[[#This Row],[Experience_Years]]<=5,"0-5 Years",Teacher_Data[[#This Row],[Experience_Years]]<=10,"5-10 Years",Teacher_Data[[#This Row],[Experience_Years]]<=20,"11-20 Years",TRUE,"20+ Years") -> 20+ Years
A33: T0032 | B33: Suresh R | C33: Male | D33: 45 | E33: International School | F33: Science | G33: Inclusive Education | H33: Assessment | I33: Hybrid | J33: 45343 | K33: 45392 | L33: In Progress | M33: 99 | O33: No | P33: 50 | Q33: West | R33: Kerala | S33: teacher32@school.edu | T33: 14 | U33: =IF(Teacher_Data[[#This Row],[Completion_Status]]="Completed","Yes","No") -> No | V33: =IF(Teacher_Data[[#This Row],[Completion_Status]]="Completed",1,0) -> 0 | W33: =1 -> 1 | X33: =Teacher_Data[[#This Row],[End_Date]]-Teacher_Data[[#This Row],[Start_Date]] -> 49 | Y33: =_xlfn.IFS(Teacher_Data[[#This Row],[Experience_Years]]<=5,"0-5 Years",Teacher_Data[[#This Row],[Experience_Years]]<=10,"5-10 Years",Teacher_Data[[#This Row],[Experience_Years]]<=20,"11-20 Years",TRUE,"20+ Years") -> 11-20 Years
A34: T0033 | B34: Ravi K | C34: Female | D34: 51 | E34: Govt High School | F34: Maths | G34: Inclusive Education | H34: Professional Development | I34: Online | J34: 45564 | K34: 45585 | L34: In Progress | M34: 60 | O34: No | P34: 49 | Q34: West | R34: Kerala | S34: teacher33@school.edu | T34: 26 | U34: =IF(Teacher_Data[[#This Row],[Completion_Status]]="Completed","Yes","No") -> No | V34: =IF(Teacher_Data[[#This Row],[Completion_Status]]="Completed",1,0) -> 0 | W34: =1 -> 1 | X34: =Teacher_Data[[#This Row],[End_Date]]-Teacher_Data[[#This Row],[Start_Date]] -> 21 | Y34: =_xlfn.IFS(Teacher_Data[[#This Row],[Experience_Years]]<=5,"0-5 Years",Teacher_Data[[#This Row],[Experience_Years]]<=10,"5-10 Years",Teacher_Data[[#This Row],[Experience_Years]]<=20,"11-20 Years",TRUE,"20+ Years") -> 20+ Years
A35: T0034 | B35: Ravi M | C35: Male | D35: 27 | E35: Central School | F35: English | G35: Digital Teaching | H35: Assessment | I35: Hybrid | J35: 45476 | K35: 45487 | L35: Completed | M35: 40 | N35: 56 | O35: Yes | P35: 35 | Q35: East | R35: Maharashtra | S35: teacher34@school.edu | T35: 21 | U35: =IF(Teacher_Data[[#This Row],[Completion_Status]]="Completed","Yes","No") -> Yes | V35: =IF(Teacher_Data[[#This Row],[Completion_Status]]="Completed",1,0) -> 1 | W35: =1 -> 1 | X35: =Teacher_Data[[#This Row],[End_Date]]-Teacher_Data[[#This Row],[Start_Date]] -> 11 | Y35: =_xlfn.IFS(Teacher_Data[[#This Row],[Experience_Years]]<=5,"0-5 Years",Teacher_Data[[#This Row],[Experience_Years]]<=10,"5-10 Years",Teacher_Data[[#This Row],[Experience_Years]]<=20,"11-20 Years",TRUE,"20+ Years") -> 20+ Years
A36: T0035 | B36: Kiran S | C36: Female | D36: 51 | E36: International School | F36: English | G36: Classroom Management | H36: Assessment | I36: Offline | J36: 45407 | K36: 45416 | L36: Completed | M36: 68 | N36: 56 | O36: Yes | P36: 40 | Q36: East | R36: Karnataka | S36: teacher35@school.edu | T36: 30 | U36: =IF(Teacher_Data[[#This Row],[Completion_Status]]="Completed","Yes","No") -> Yes | V36: =IF(Teacher_Data[[#This Row],[Completion_Status]]="Completed",1,0) -> 1 | W36: =1 -> 1 | X36: =Teacher_Data[[#This Row],[End_Date]]-Teacher_Data[[#This Row],[Start_Date]] -> 9 | Y36: =_xlfn.IFS(Teacher_Data[[#This Row],[Experience_Years]]<=5,"0-5 Years",Teacher_Data[[#This Row],[Experience_Years]]<=10,"5-10 Years",Teacher_Data[[#This Row],[Experience_Years]]<=20,"11-20 Years",TRUE,"20+ Years") -> 20+ Years
A37: T0036 | B37: Amit R | C37: Male | D37: 43 | E37: International School | F37: Maths | G37: EdTech Tools | H37: Professional Development | I37: Online | J37: 45328 | K37: 45337 | L37: Not Completed | M37: 2 | O37: No | P37: 52 | Q37: West | R37: Tamil Nadu | S37: teacher36@school.edu | T37: 16 | U37: =IF(Teacher_Data[[#This Row],[Completion_Status]]="Completed","Yes","No") -> No | V37: =IF(Teacher_Data[[#This Row],[Completion_Status]]="Completed",1,0) -> 0 | W37: =1 -> 1 | X37: =Teacher_Data[[#This Row],[End_Date]]-Teacher_Data[[#This Row],[Start_Date]] -> 9 | Y37: =_xlfn.IFS(Teacher_Data[[#This Row],[Experience_Years]]<=5,"0-5 Years",Teacher_Data[[#This Row],[Experience_Years]]<=10,"5-10 Years",Teacher_Data[[#This Row],[Experience_Years]]<=20,"11-20 Years",TRUE,"20+ Years") -> 11-20 Years
A38: T0037 | B38: Amit R | C38: Female | D38: 48 | E38: Govt High School | F38: Science | G38: EdTech Tools | H38: Assessment | I38: Online | J38: 45556 | K38: 45572 | L38: Completed | M38: 76 | N38: 97 | O38: Yes | P38: 29 | Q38: West | R38: Kerala | S38: teacher37@school.edu | T38: 8 | U38: =IF(Teacher_Data[[#This Row],[Completion_Status]]="Completed","Yes","No") -> Yes | V38: =IF(Teacher_Data[[#This Row],[Completion_Status]]="Completed",1,0) -> 1 | W38: =1 -> 1 | X38: =Teacher_Data[[#This Row],[End_Date]]-Teacher_Data[[#This Row],[Start_Date]] -> 16 | Y38: =_xlfn.IFS(Teacher_Data[[#This Row],[Experience_Years]]<=5,"0-5 Years",Teacher_Data[[#This Row],[Experience_Years]]<=10,"5-10 Years",Teacher_Data[[#This Row],[Experience_Years]]<=20,"11-20 Years",TRUE,"20+ Years") -> 5-10 Years
A39: T0038 | B39: Rahul S | C39: Male | D39: 23 | E39: Public School | F39: Science | G39: Assessment Skills | H39: Professional Development | I39: Hybrid | J39: 45410 | K39: 45422 | L39: In Progress | M39: 56 | O39: No | P39: 18 | Q39: East | R39: Kerala | S39: teacher38@school.edu | T39: 15 | U39: =IF(Teacher_Data[[#This Row],[Completion_Status]]="Completed","Yes","No") -> No | V39: =IF(Teacher_Data[[#This Row],[Completion_Status]]="Completed",1,0) -> 0 | W39: =1 -> 1 | X39: =Teacher_Data[[#This Row],[End_Date]]-Teacher_Data[[#This Row],[Start_Date]] -> 12 | Y39: =_xlfn.IFS(Teacher_Data[[#This Row],[Experience_Years]]<=5,"0-5 Years",Teacher_Data[[#This Row],[Experience_Years]]<=10,"5-10 Years",Teacher_Data[[#This Row],[Experience_Years]]<=20,"11-20 Years",TRUE,"20+ Years") -> 11-20 Years
A40: T0039 | B40: Ravi R | C40: Male | D40: 60 | E40: International School | F40: Computer Science | G40: Classroom Management | H40: Assessment | I40: Hybrid | J40: 45458 | K40: 45476 | L40: In Progress | M40: 79 | O40: No | P40: 12 | Q40: South | R40: Tamil Nadu | S40: teacher39@school.edu | T40: 18 | U40: =IF(Teacher_Data[[#This Row],[Completion_Status]]="Completed","Yes","No") -> No | V40: =IF(Teacher_Data[[#This Row],[Completion_Status]]="Completed",1,0) -> 0 | W40: =1 -> 1 | X40: =Teacher_Data[[#This Row],[End_Date]]-Teacher_Data[[#This Row],[Start_Date]] -> 18 | Y40: =_xlfn.IFS(Teacher_Data[[#This Row],[Experience_Years]]<=5,"0-5 Years",Teacher_Data[[#This Row],[Experience_Years]]<=10,"5-10 Years",Teacher_Data[[#This Row],[Experience_Years]]<=20,"11-20 Years",TRUE,"20+ Years") -> 11-20 Years
...
